Workbook

Sheet Вигрузка
A1: ='MultiPlus & Sunlight'!H1 -> Артикул | B1: ='MultiPlus & Sunlight'!I1 -> Ціна | C1: стара ціна | D1: Валюта | E1: Відображати | F1: Наявність | G1: Назва юа | H1: Назва ру | I1: Назва мод юа | J1: Назва мод ру | K1: Раздел | N1: текст юа | O1: текст ру
A2: ='MultiPlus & Sunlight'!H2 -> TMS4801001003 | B2: ='MultiPlus & Sunlight'!I2 -> 2087.44 | C2: 0 | D2: EUR | E2: Да | F2: В наявності | G2: Комплект безперебійного живлення TMS 230В 3кВА – 2,4кВт з акумулятором 5кВт.г | H2: Комплект бесперебойного питания TMS 230В 3 кВА – 2,4 кВт с аккумулятором 5 кВт.ч | I2: Комплект безперебійного живлення TMS 230В 3кВА – 2,4кВт з акумулятором 5кВт.г | J2: Комплект бесперебойного питания TMS 230В 3 кВА – 2,4 кВт с аккумулятором 5 кВт.ч | K2: Каталог/Комплекти безперебійного живлення
A3: ='MultiPlus & Sunlight'!H3 -> TMS4801001003GX | B3: ='MultiPlus & Sunlight'!I3 -> 2191.84 | C3: 0 | D3: EUR | E3: Да | F3: В наявності | G3: Комплект безперебійного живлення TMS 230В 3кВА – 2,4кВт з акумулятором 5кВт.г з WiFi | H3: Комплект бесперебойного питания TMS 230В 3 кВА – 2,4 кВт с аккумулятором 5 кВт.ч с WiFi | I3: Комплект безперебійного живлення TMS 230В 3кВА – 2,4кВт з акумулятором 5кВт.г з WiFi | J3: Комплект бесперебойного питания TMS 230В 3 кВА – 2,4 кВт с аккумулятором 5 кВт.ч с WiFi | K3: Каталог/Комплекти безперебійного живлення
A4: ='MultiPlus & Sunlight'!H4 -> TMS4802001005 | B4: ='MultiPlus & Sunlight'!I4 -> 3981.56 | C4: 0 | D4: EUR | E4: Да | F4: В наявності | G4: Комплект безперебійного живлення TMS 230В 5кВА – 4кВт з акумулятором 10кВт.г | H4: Комплект бесперебойного питания TMS 230В 5 кВА – 4 кВт с аккумулятором 10 кВт.ч | I4: Комплект безперебійного живлення TMS 230В 5кВА – 4кВт з акумулятором 10кВт.г | J4: Комплект бесперебойного питания TMS 230В 5 кВА – 4 кВт с аккумулятором 10 кВт.ч | K4: Каталог/Комплекти безперебійного живлення
A5: ='MultiPlus & Sunlight'!H5 -> TMS4802001005GX | B5: ='MultiPlus & Sunlight'!I5 -> 4217.96 | C5: 0 | D5: EUR | E5: Да | F5: В наявності | G5: Комплект безперебійного живлення TMS 230В 5кВА – 4кВт з акумулятором 10кВт.г з WiFi | H5: Комплект бесперебойного питания TMS 230В 5 кВА – 4 кВт с аккумулятором 10 кВт.ч с WiFi | I5: Комплект безперебійного живлення TMS 230В 5кВА – 4кВт з акумулятором 10кВт.г з WiFi | J5: Комплект бесперебойного питания TMS 230В 5 кВА – 4 кВт с аккумулятором 10 кВт.ч с WiFi | K5: Каталог/Комплекти безперебійного живлення
A6: ='MultiPlus & Sunlight'!H6 -> TMS4803001005GX | B6: ='MultiPlus & Sunlight'!I6 -> 5473.08 | C6: 0 | D6: EUR | E6: Да | F6: В наявності | G6: Комплект безперебійного живлення TMS 230В 5кВА – 4кВт з акумулятором 15кВт.г з WiFi | H6: Комплект бесперебойного питания TMS 230В 5 кВА – 4 кВт с аккумулятором 15 кВт.ч с WiFi | I6: Комплект безперебійного живлення TMS 230В 5кВА – 4кВт з акумулятором 15кВт.г з WiFi | J6: Комплект бесперебойного питания TMS 230В 5 кВА – 4 кВт с аккумулятором 15 кВт.ч с WiFi | K6: Каталог/Комплекти безперебійного живлення
A7: ='MultiPlus & Sunlight'!H7 -> TMS4802001008GX | B7: ='MultiPlus & Sunlight'!I7 -> 5271.36 | C7: 0 | D7: EUR | E7: Да | F7: В наявності | G7: Комплект безперебійного живлення TMS 230В 8кВА – 6,4кВт з акумулятором 10кВт.г з WiFi | H7: Комплект бесперебойного питания TMS 230В 8 кВА – 6,4 кВт с аккумулятором 10 кВт.ч с WiFi | I7: Комплект безперебійного живлення TMS 230В 8кВА – 6,4кВт з акумулятором 10кВт.г з WiFi | J7: Комплект бесперебойного питания TMS 230В 8 кВА – 6,4 кВт с аккумулятором 10 кВт.ч с WiFi | K7: Каталог/Комплекти безперебійного живлення
A8: ='MultiPlus & Sunlight'!H8 -> TMS4803001008GX | B8: ='MultiPlus & Sunlight'!I8 -> 6526.48 | C8: 0 | D8: EUR | E8: Да | F8: В наявності | G8: Комплект безперебійного живлення TMS 230В 8кВА – 6,4кВт з акумулятором 15кВт.г з WiFi | H8: Комплект бесперебойного питания TMS 230В 8 кВА – 6,4 кВт с аккумулятором 15 кВт.ч с WiFi | I8: Комплект безперебійного живлення TMS 230В 8кВА – 6,4кВт з акумулятором 15кВт.г з WiFi | J8: Комплект бесперебойного питания TMS 230В 8 кВА – 6,4 кВт с аккумулятором 15 кВт.ч с WiFi | K8: Каталог/Комплекти безперебійного живлення
A9: ='MultiPlus & Sunlight'!H9 -> TMS4803001010GX | B9: ='MultiPlus & Sunlight'!I9 -> 6834.88 | C9: 0 | D9: EUR | E9: Да | F9: В наявності | G9: Комплект безперебійного живлення TMS 230В 10кВА – 8кВт з акумулятором 15кВт.г з WiFi | H9: Комплект бесперебойного питания TMS 230В 10 кВА – 8 кВт с аккумулятором 15 кВт.ч с WiFi | I9: Комплект безперебійного живлення TMS 230В 10кВА – 8кВт з акумулятором 15кВт.г з WiFi | J9: Комплект бесперебойного питания TMS 230В 10 кВА – 8 кВт с аккумулятором 15 кВт.ч с WiFi | K9: Каталог/Комплекти безперебійного живлення
A10: ='MultiPlus & Sunlight'!H10 -> TMS4804001010GX | B10: ='MultiPlus & Sunlight'!I10 -> 8290 | C10: 0 | D10: EUR | E10: Да | F10: В наявності | G10: Комплект безперебійного живлення TMS 230В 10кВА – 8кВт з акумулятором 20кВт.г з WiFi | H10: Комплект бесперебойного питания TMS 230В 10 кВА – 8 кВт с аккумулятором 20 кВт.ч с WiFi | I10: Комплект безперебійного живлення TMS 230В 10кВА – 8кВт з акумулятором 20кВт.г з WiFi | J10: Комплект бесперебойного питания TMS 230В 10 кВА – 8 кВт с аккумулятором 20 кВт.ч с WiFi | K10: Каталог/Комплекти безперебійного живлення
A11: ='MultiPlus & Sunlight'!H11 -> TMS4804001015GX | B11: ='MultiPlus & Sunlight'!I11 -> 9177.52 | C11: 0 | D11: EUR | E11: Да | F11: В наявності | G11: Комплект безперебійного живлення TMS 230В 15кВА – 12кВт з акумулятором 20кВт.г з WiFi | H11: Комплект бесперебойного питания TMS 230В 15 кВА – 12 кВт с аккумулятором 20 кВт.ч с WiFi | I11: Комплект безперебійного живлення TMS 230В 15кВА – 12кВт з акумулятором 20кВт.г з WiFi | J11: Комплект бесперебойного питания TMS 230В 15 кВА – 12 кВт с аккумулятором 20 кВт.ч с WiFi | K11: Каталог/Комплекти безперебійного живлення
A12: ='MultiPlus & Sunlight'!H12 -> TMS4805001015GX | B12: ='MultiPlus & Sunlight'!I12 -> 10437.64 | C12: 0 | D12: EUR | E12: Да | F12: В наявності | G12: Комплект безперебійного живлення TMS 230В 15кВА – 12кВт з акумулятором 25кВт.г з WiFi | H12: Комплект бесперебойного питания TMS 230В 15 кВА – 12 кВт с аккумулятором 25 кВт.ч с WiFi | I12: Комплект безперебійного живлення TMS 230В 15кВА – 12кВт з акумулятором 25кВт.г з WiFi | J12: Комплект бесперебойного питания TMS 230В 15 кВА – 12 кВт с аккумулятором 25 кВт.ч с WiFi | K12: Каталог/Комплекти безперебійного живлення
A13: ='MultiPlus & Sunlight'!H13 -> TMS4806001015GX | B13: ='MultiPlus & Sunlight'!I13 -> 11692.76 | C13: 0 | D13: EUR | E13: Да | F13: В наявності | G13: Комплект безперебійного живлення TMS 230В 15кВА – 12кВт з акумулятором 30кВт.г з WiFi | H13: Комплект бесперебойного питания TMS 230В 15 кВА – 12 кВт с аккумулятором 30 кВт.ч с WiFi | I13: Комплект безперебійного живлення TMS 230В 15кВА – 12кВт з акумулятором 30кВт.г з WiFi | J13: Комплект бесперебойного питания TMS 230В 15 кВА – 12 кВт с аккумулятором 30 кВт.ч с WiFi | K13: Каталог/Комплекти безперебійного живлення
... A29: ='MultiPlus & Sunlight'!H29 -> TMS4815003045GX | B29: ='MultiPlus & Sunlight'!I29 -> 30676.92 | C29: 0 | D29: EUR | E29: Да | F29: В наявності | G29: Комплект безперебійного живлення TMS 400В 45кВА – 36кВт з акумулятором 75кВт.г з WiFi | H29: Комплект бесперебойного питания TMS 400В 45 кВА – 36 кВт с аккумулятором 75 кВт.ч с WiFi | I29: Комплект безперебійного живлення TMS 400В 45кВА – 36кВт з акумулятором 75кВт.г з WiFi | J29: Комплект бесперебойного питания TMS 400В 45 кВА – 36 кВт с аккумулятором 75 кВт.ч с WiFi | K29: Каталог/Комплекти безперебійного живлення
A30: ='Quattro & Sunlight'!H3 -> TQS4802001005GX | B30: ='Quattro & Sunlight'!I3 -> 4740.96 | C30: 0 | D30: EUR | E30: Да | F30: В наявності | G30: Комплект безперебійного живлення 230В 5кВА – 4кВт з акумулятором 10кВт.г з WiFi | H30: Комплект бесперебойного питания 230В 5 кВА – 4 кВт с аккумулятором 10 кВт.ч с WiFi | I30: Комплект безперебійного живлення 230В 5кВА – 4кВт з акумулятором 10кВт.г з WiFi | J30: Комплект бесперебойного питания 230В 5 кВА – 4 кВт с аккумулятором 10 кВт.ч с WiFi | K30: Каталог/Комплекти безперебійного живлення
A31: ='Quattro & Sunlight'!H4 -> TQS4803001005GX | B31: ='Quattro & Sunlight'!I4 -> 5996.08 | C31: 0 | D31: EUR | E31: Да | F31: В наявності | G31: Комплект безперебійного живлення 230В 5кВА – 4кВт з акумулятором 15кВт.г з WiFi | H31: Комплект бесперебойного питания 230В 5 кВА – 4 кВт с аккумулятором 15 кВт.ч с WiFi | I31: Комплект безперебійного живлення 230В 5кВА – 4кВт з акумулятором 15кВт.г з WiFi | J31: Комплект бесперебойного питания 230В 5 кВА – 4 кВт с аккумулятором 15 кВт.ч с WiFi | K31: Каталог/Комплекти безперебійного живлення
A32: ='Quattro & Sunlight'!H5 -> TQS4802001008GX | B32: ='Quattro & Sunlight'!I5 -> 5731.96 | C32: 0 | D32: EUR | E32: Да | F32: В наявності | G32: Комплект безперебійного живлення 230В 8кВА – 6,4кВт з акумулятором 10кВт.г з WiFi | H32: Комплект бесперебойного питания 230В 8 кВА – 6,4 кВт с аккумулятором 10 кВт.ч с WiFi | I32: Комплект безперебійного живлення 230В 8кВА – 6,4кВт з акумулятором 10кВт.г з WiFi | J32: Комплект бесперебойного питания 230В 8 кВА – 6,4 кВт с аккумулятором 10 кВт.ч с WiFi | K32: Каталог/Комплекти безперебійного живлення
A33: ='Quattro & Sunlight'!H6 -> TQS4803001008GX | B33: ='Quattro & Sunlight'!I6 -> 6987.08 | C33: 0 | D33: EUR | E33: Да | F33: В наявності | G33: Комплект безперебійного живлення 230В 8кВА – 6,4кВт з акумулятором 15кВт.г з WiFi | H33: Комплект бесперебойного питания 230В 8 кВА – 6,4 кВт с аккумулятором 15 кВт.ч с WiFi | I33: Комплект безперебійного живлення 230В 8кВА – 6,4кВт з акумулятором 15кВт.г з WiFi | J33: Комплект бесперебойного питания 230В 8 кВА – 6,4 кВт с аккумулятором 15 кВт.ч с WiFi | K33: Каталог/Комплекти безперебійного живлення
A34: ='Quattro & Sunlight'!H7 -> TQS4803001010GX | B34: ='Quattro & Sunlight'!I7 -> 7498.28 | C34: 0 | D34: EUR | E34: Да | F34: В наявності | G34: Комплект безперебійного живлення 230В 10кВА – 8кВт з акумулятором 15кВт.г з WiFi | H34: Комплект бесперебойного питания 230В 10 кВА – 8 кВт с аккумулятором 15 кВт.ч с WiFi | I34: Комплект безперебійного живлення 230В 10кВА – 8кВт з акумулятором 15кВт.г з WiFi | J34: Комплект бесперебойного питания 230В 10 кВА – 8 кВт с аккумулятором 15 кВт.ч с WiFi | K34: Каталог/Комплекти безперебійного живлення
A35: ='Quattro & Sunlight'!H8 -> TQS4804001010GX | B35: ='Quattro & Sunlight'!I8 -> 8953.4 | C35: 0 | D35: EUR | E35: Да | F35: В наявності | G35: Комплект безперебійного живлення 230В 10кВА – 8кВт з акумулятором 20кВт.г з WiFi | H35: Комплект бесперебойного питания 230В 10 кВА – 8 кВт с аккумулятором 20 кВт.ч с WiFi | I35: Комплект безперебійного живлення 230В 10кВА – 8кВт з акумулятором 20кВт.г з WiFi | J35: Комплект бесперебойного питания 230В 10 кВА – 8 кВт с аккумулятором 20 кВт.ч с WiFi | K35: Каталог/Комплекти безперебійного живлення
A36: ='Quattro & Sunlight'!H9 -> TQS4805001010GX | B36: ='Quattro & Sunlight'!I9 -> 10213.52 | C36: 0 | D36: EUR | E36: Да | F36: В наявності | G36: Комплект безперебійного живлення 230В 10кВА – 8кВт з акумулятором 25кВт.г з WiFi | H36: Комплект бесперебойного питания 230В 10 кВА – 8 кВт с аккумулятором 25 кВт.ч с WiFi | I36: Комплект безперебійного живлення 230В 10кВА – 8кВт з акумулятором 25кВт.г з WiFi | J36: Комплект бесперебойного питания 230В 10 кВА – 8 кВт с аккумулятором 25 кВт.ч с WiFi | K36: Каталог/Комплекти безперебійного живлення
A37: ='Quattro & Sunlight'!H10 -> TQS4804001015GX | B37: ='Quattro & Sunlight'!I10 -> 9860.12 | C37: 0 | D37: EUR | E37: Да | F37: В наявності | G37: Комплект безперебійного живлення 230В 15кВА – 12кВт з акумулятором 20кВт.г з WiFi | H37: Комплект бесперебойного питания 230В 15 кВА – 12 кВт с аккумулятором 20 кВт.ч с WiFi | I37: Комплект безперебійного живлення 230В 15кВА – 12кВт з акумулятором 20кВт.г з WiFi | J37: Комплект бесперебойного питания 230В 15 кВА – 12 кВт с аккумулятором 20 кВт.ч с WiFi | K37: Каталог/Комплекти безперебійного живлення
A38: ='Quattro & Sunlight'!H11 -> TQS4805001015GX | B38: ='Quattro & Sunlight'!I11 -> 11120.24 | C38: 0 | D38: EUR | E38: Да | F38: В наявності | G38: Комплект безперебійного живлення 230В 15кВА – 12кВт з акумулятором 25кВт.г з WiFi | H38: Комплект бесперебойного питания 230В 15 кВА – 12 кВт с аккумулятором 25 кВт.ч с WiFi | I38: Комплект безперебійного живлення 230В 15кВА – 12кВт з акумулятором 25кВт.г з WiFi | J38: Комплект бесперебойного питания 230В 15 кВА – 12 кВт с аккумулятором 25 кВт.ч с WiFi | K38: Каталог/Комплекти безперебійного живлення
A39: ='Quattro & Sunlight'!H12 -> TQS4806001015GX | B39: ='Quattro & Sunlight'!I12 -> 12375.36 | C39: 0 | D39: EUR | E39: Да | F39: В наявності | G39: Комплект безперебійного живлення 230В 15кВА – 12кВт з акумулятором 30кВт.г з WiFi | H39: Комплект бесперебойного питания 230В 15 кВА – 12 кВт с аккумулятором 30 кВт.ч с WiFi | I39: Комплект безперебійного живлення 230В 15кВА – 12кВт з акумулятором 30кВт.г з WiFi | J39: Комплект бесперебойного питания 230В 15 кВА – 12 кВт с аккумулятором 30 кВт.ч с WiFi | K39: Каталог/Комплекти безперебійного живлення
A40: ='Quattro & Sunlight'!H13 -> TQS4803003015GX | B40: ='Quattro & Sunlight'!I13 -> 9341.52 | C40: 0 | D40: EUR | E40: Да | F40: В наявності | G40: Комплект безперебійного живлення 400В 15кВА – 12кВт з акумулятором 15кВт.г з WiFi | H40: Комплект бесперебойного питания 400В 15 кВА – 12 кВт с аккумулятором 15 кВт.ч с WiFi | I40: Комплект безперебійного живлення 400В 15кВА – 12кВт з акумулятором 15кВт.г з WiFi | J40: Комплект бесперебойного питания 400В 15 кВА – 12 кВт с аккумулятором 15 кВт.ч с WiFi | K40: Каталог/Комплекти безперебійного живлення
A41: ='Quattro & Sunlight'!H14 -> TQS4804003015GX | B41: ='Quattro & Sunlight'!I14 -> 10616.64 | C41: 0 | D41: EUR | E41: Да | F41: В наявності | G41: Комплект безперебійного живлення 400В 15кВА – 12кВт з акумулятором 20кВт.г з WiFi | H41: Комплект бесперебойного питания 400В 15 кВА – 12 кВт с аккумулятором 20 кВт.ч с WiFi | I41: Комплект безперебійного живлення 400В 15кВА – 12кВт з акумулятором 20кВт.г з WiFi | J41: Комплект бесперебойного питания 400В 15 кВА – 12 кВт с аккумулятором 20 кВт.ч с WiFi | K41: Каталог/Комплекти безперебійного живлення
... A52: ='Quattro & Sunlight'!H25 -> TQS4820003045GX | B52: ='Quattro & Sunlight'!I25 -> 39105.32 | C52: 0 | D52: EUR | E52: Да | F52: В наявності | G52: Комплект безперебійного живлення 400В 45кВА – 36кВт з акумулятором 100кВт.г з WiFi | H52: Комплект бесперебойного питания 400В 45 кВА – 36 кВт с аккумулятором 100 кВт.ч с WiFi | I52: Комплект безперебійного живлення 400В 45кВА – 36кВт з акумулятором 100кВт.г з WiFi | J52: Комплект бесперебойного питания 400В 45 кВА – 36 кВт с аккумулятором 100 кВт.ч с WiFi | K52: Каталог/Комплекти безперебійного живлення

Sheet Компонети
D2: Ціна без ПДВ | E2: Множник ПДВ | F2: Ціна з ПДВ
A3: Victron Energy | B3: MultiPlus-II 48/3000/35-32 | C3: PMP482305010 | D3: =624 -> 624 | E3: 1.2 | F3: =D3*E3 -> 748.8 | G3: EUR
A4: Victron Energy | B4: MultiPlus-II 48/3000/35-32 GX | C4: PMP482306000 | D4: 711 | E4: 1.2 | F4: =D4*E4 -> 853.2 | G4: EUR
A5: Victron Energy | B5: MultiPlus-II 48/5000/70-50 | C5: PMP482505012 | D5: 844 | E5: 1.2 | F5: =D5*E5 -> 1012.8 | G5: EUR
A6: Victron Energy | B6: MultiPlus-II 48/5000/70-50-GX | C6: PMP482506000 | D6: 1041 | E6: 1.2 | F6: =D6*E6 -> 1249.2 | G6: EUR
A7: Victron Energy | B7: MultiPlus-II 48/8000/110-100 | C7: PMP482805000 | D7: 1633 | E7: 1.2 | F7: =D7*E7 -> 1959.6 | G7: EUR
A8: Victron Energy | B8: MultiPlus-II 48/10000/140-100 | C8: PMP483105000 | D8: 1853 | E8: 1.2 | F8: =D8*E8 -> 2223.6 | G8: EUR
A9: Victron Energy | B9: MultiPlus-II 48/15000/200-100 | C9: PMP483150000 | D9: 2585 | E9: 1.2 | F9: =D9*E9 -> 3102 | G9: EUR
A10: Victron Energy | B10: Quattro 48/5000/70-100/100 | C10: QUA485021010 | D10: 1764 | E10: 1.2 | F10: =D10*E10 -> 2116.8 | G10: EUR
A11: Victron Energy | B11: Quattro-II 48/5000/70-50/50 | C11: QUA482504010 | D11: 1191 | E11: 1.2 | F11: =D11*E11 -> 1429.2 | G11: EUR
A12: Victron Energy | B12: Quattro 48/8000/110-100/100 | C12: QUA488024000 | D12: 1996 | E12: 1.2 | F12: =D12*E12 -> 2395.2 | G12: EUR
A13: Victron Energy | B13: Quattro 48/10000/140-100/100 | C13: QUA481030010 | D13: 2385 | E13: 1.2 | F13: =D13*E13 -> 2862 | G13: EUR
A14: Victron Energy | B14: Quattro 48/15000/200-100/100 | C14: QUA483150000 | D14: 3133 | E14: 1.2 | F14: =D14*E14 -> 3759.6 | G14: EUR
A19: Victron Energy | B19: Cerbo GX MK2 | C19: BPP900451100 | D19: 265 | E19: 1.2 | F19: =E19*D19 -> 318 | G19: EUR
A20: Victron Energy | B20: Lynx Power In (M10) | C20: LYN020102000 | D20: 150 | E20: 1.2 | F20: =E20*D20 -> 180 | G20: EUR
A21: Victron Energy | B21: Battery switch on/off 275A | C21: VBS127010010 | D21: 37 | E21: 1.2 | F21: =E21*D21 -> 44.4 | G21: EUR
A22: Victron Energy | B22: MEGA-fuse 100A/80V | C22: CIP138100020 | D22: =38/5 -> 7.6 | E22: 1.2 | F22: =E22*D22 -> 9.12 | G22: EUR
A23: Victron Energy | B23: MEGA-fuse 120A/80V | C23: CIP138125020 | D23: =38/5 -> 7.6 | E23: 1.2 | F23: =E23*D23 -> 9.12 | G23: EUR
A24: Victron Energy | B24: MEGA-fuse 200A/80V | C24: CIP138200020 | D24: =38/5 -> 7.6 | E24: 1.2 | F24: =E24*D24 -> 9.12 | G24: EUR
A25: Victron Energy | B25: MEGA-fuse 250A/80V | C25: CIP138250020 | D25: =38/5 -> 7.6 | E25: 1.2 | F25: =E25*D25 -> 9.12 | G25: EUR
A26: Victron Energy | B26: MEGA-fuse 300A/80V | C26: CIP138300020 | D26: =38/5 -> 7.6 | E26: 1.2 | F26: =E26*D26 -> 9.12 | G26: EUR
A27: Victron Energy | B27: MEGA-fuse 400A/80V | C27: CIP138400020 | D27: =38/5 -> 7.6 | E27: 1.2 | F27: =E27*D27 -> 9.12 | G27: EUR
A28: Victron Energy | B28: MEGA-fuse 500A/80V | C28: CIP138500020 | D28: =38/5 -> 7.6 | E28: 1.2 | F28: =E28*D28 -> 9.12 | G28: EUR
A29: Victron Energy | B29: Тримач запобіжника Victron для MEGA-fuse | C29: CIP000100001 | D29: =38/5 -> 7.6 | E29: 1.2 | F29: =E29*D29 -> 9.12 | G29: EUR
A31: Sacred Sun | B31: Акумулятор LiFePO4 Sacred Sun SLSIFP48100A(3U) 48В 100Аг з вбудованим BMS та підтримкою CAN-шини | C31: SLSIFP48100A | E31: 1038 USD | F31: 896 | G31: EUR
A32: Sunlight | B32: Акумулятор Sunlight Power ESS 51.2V 100Ah LiFePO4 | C32: SUNPOW51100 | F32: 1226 | G32: EUR
A34: Total Energo | B34: Налаштування інвертора MultiPlus з LiFePO₄ акумуляторами | C34: 62 | F34: 75 | G34: EUR
A35: Total Energo | B35: Налаштування інвертора Quattro з LiFePO₄ акумуляторами | C35: 63 | F35: 100 | G35: EUR
A36: Total Energo | B36: Налаштування трифазної конфігурації MultiPlus | C36: 66 | F36: 200 | G36: EUR
A37: Total Energo | B37: Налаштування трифазної конфігурації Quattro | C37: 67 | F37: 200 | G37: EUR
A38: Total Energo | B38: Інсталяційний набір витратних матеріалів 230В 3-5кВт | C38: INS48305080 | F38: 50 | G38: EUR
A39: Total Energo | B39: Інсталяційний набір витратних матеріалів 230В 10-15кВт | C39: INS48100150 | F39: 75 | G39: EUR
A40: Total Energo | B40: Інсталяційний набір витратних матеріалів 400В 15-20кВт | C40: INS48150200 | F40: 150 | G40: EUR
A41: Total Energo | B41: Інсталяційний набір витратних матеріалів 400В 24-30кВт | C41: INS48250300 | F41: 250 | G41: EUR
A42: Total Energo | B42: Стійка для АКБ 16U | C42: ESR1916U | F42: 100 | G42: EUR
A43: Total Energo | B43: Стійка для АКБ 24U | C43: ESR1924U | F43: 120 | G43: EUR
A44: Total Energo | B44: Стійка для АКБ 32U | C44: ESR1932U | F44: 125 | G44: EUR
A45: Total Energo | B45: Полиця для АКБ | C45: ESS1901U | F45: 20 | G45: EUR

Sheet MultiPlus & Sunlight
H1: Артикул | I1: Ціна
A2: Total Energo | B2: Комплект безперебійного живлення TMS 230В 3кВА – 2,4кВт з акумулятором 5кВт*г | C2: TMS4801001003 | D2: Кількість | E2: Вартість з ПДВ | F2: Варість * Кількість | H2: =C2 -> TMS4801001003 | I2: =F9 -> 2087.44
C3: PMP482305010 | D3: 1 | E3: =Компонети!$F$3 -> 748.8 | F3: =E3*D3 -> 748.8 | H3: =C10 -> TMS4801001003GX | I3: =F17 -> 2191.84
C4: SUNPOW51100 | D4: 1 | E4: =Компонети!$F$32 -> 1226 | F4: =E4*D4 -> 1226 | H4: =C18 -> TMS4802001005 | I4: =F29 -> 3981.56
C5: VBS127010010 | D5: 1 | E5: =Компонети!$F$21 -> 44.4 | F5: =E5*D5 -> 44.4 | H5: =C30 -> TMS4802001005GX | I5: =F41 -> 4217.96
C6: CIP000100001 | D6: 1 | E6: =Компонети!$F$29 -> 9.12 | F6: =E6*D6 -> 9.12 | H6: =C42 -> TMS4803001005GX | I6: =F53 -> 5473.08
C7: CIP138100020 | D7: 1 | E7: =Компонети!$F$22 -> 9.12 | F7: =E7*D7 -> 9.12 | H7: =C54 -> TMS4802001008GX | I7: =F66 -> 5271.36
C8: INS48305080 | D8: 1 | E8: =Компонети!$F$38 -> 50 | F8: =E8*D8 -> 50 | H8: =C67 -> TMS4803001008GX | I8: =F79 -> 6526.48
E9: Сума підсумкова | F9: =SUM(F3:F8) -> 2087.44 | H9: =C80 -> TMS4803001010GX | I9: =F92 -> 6834.88
A10: Total Energo | B10: Комплект безперебійного живлення TMS 230В 3кВА – 2,4кВт з акумулятором 5кВт*г з WiFi | C10: TMS4801001003GX | H10: =C93 -> TMS4804001010GX | I10: =F105 -> 8290
C11: PMP482306000 | D11: 1 | E11: =Компонети!$F$4 -> 853.2 | F11: =E11*D11 -> 853.2 | H11: =C106 -> TMS4804001015GX | I11: =F118 -> 9177.52
C12: SUNPOW51100 | D12: 1 | E12: =Компонети!$F$32 -> 1226 | F12: =E12*D12 -> 1226 | H12: =C119 -> TMS4805001015GX | I12: =F131 -> 10437.64
C13: VBS127010010 | D13: 1 | E13: =Компонети!$F$21 -> 44.4 | F13: =E13*D13 -> 44.4 | H13: =C132 -> TMS4806001015GX | I13: =F144 -> 11692.76
C14: CIP000100001 | D14: 1 | E14: =Компонети!$F$29 -> 9.12 | F14: =E14*D14 -> 9.12 | H14: =C146 -> TMS4802003009GX | I14: =F158 -> 6045.2
C15: CIP138100020 | D15: 1 | E15: =Компонети!$F$22 -> 9.12 | F15: =E15*D15 -> 9.12 | H15: =C159 -> TMS4803003009GX | I15: =F171 -> 7300.32
C16: INS48305080 | D16: 1 | E16: =Компонети!$F$38 -> 50 | F16: =E16*D16 -> 50 | H16: =C172 -> TMS4804003009GX | I16: =F184 -> 8575.44
E17: Сума підсумкова | F17: =SUM(F11:F16) -> 2191.84 | H17: =C185 -> TMS4803003015GX | I17: =F197 -> 8092.32
A18: Total Energo | B18: Комплект безперебійного живлення TMS 230В 5кВА – 4кВт з акумулятором 10кВт*г | C18: TMS4802001005 | H18: =C198 -> TMS4804003015GX | I18: =F210 -> 9367.44
C19: PMP482505010 | D19: 1 | E19: =Компонети!$F$5 -> 1012.8 | F19: =E19*D19 -> 1012.8 | H19: =C211 -> TMS4805003015GX | I19: =F223 -> 10627.56
C20: LYN020102000 | D20: 1 | E20: =Компонети!$F$20 -> 180 | F20: =E20*D20 -> 180 | H20: =C224 -> TMS4805003024GX | I20: =F236 -> 13567.96
C21: VBS127010010 | D21: 1 | E21: =Компонети!$F$21 -> 44.4 | F21: =E21*D21 -> 44.4 | H21: =C237 -> TMS4806003024GX | I21: =F249 -> 15003.08
C22: CIP138100020 | D22: 2 | E22: =Компонети!$F$22 -> 9.12 | F22: =E22*D22 -> 18.24 | H22: =C250 -> TMS4808003024GX | I22: =F262 -> 17628.32
C23: CIP138200020 | D23: 1 | E23: =Компонети!$F$24 -> 9.12 | F23: =E23*D23 -> 9.12 | H23: =C263 -> TMS4810003024GX | I23: =F275 -> 20148.56
C24: SUNPOW51100 | D24: 2 | E24: =Компонети!$F$32 -> 1226 | F24: =E24*D24 -> 2452 | H24: =C276 -> TMS4808003030GX | I24: =F288 -> 18760.88
C25: 62 | D25: 1 | E25: =Компонети!$F$34 -> 75 | F25: =E25*D25 -> 75 | H25: =C289 -> TMS4810003030GX | I25: =F301 -> 21281.12
C26: INS48305080 | D26: 1 | E26: =Компонети!$F$38 -> 50 | F26: =E26*D26 -> 50 | H26: =C302 -> TMS4812003030GX | I26: =F314 -> 24081.36
C27: ESR1916U | D27: 1 | E27: =Компонети!$F$42 -> 100 | F27: =E27*D27 -> 100 | H27: =C315 -> TMS4809003045GX | I27: =F327 -> 22661.2
C28: ESS1901U | D28: 2 | E28: =Компонети!$F$45 -> 20 | F28: =E28*D28 -> 40 | H28: =C328 -> TMS4812003045GX | I28: =F340 -> 26606.56
E29: Сума підсумкова | F29: =SUM(F19:F28) -> 3981.56 | H29: =C341 -> TMS4815003045GX | I29: =F353 -> 30676.92
A30: Total Energo | B30: Комплект безперебійного живлення TMS 230В 5кВА – 4кВт з акумулятором 10кВт*г з WiFi | C30: TMS4802001005GX
C31: PMP482506000 | D31: 1 | E31: =Компонети!$F$6 -> 1249.2 | F31: =E31*D31 -> 1249.2
C32: LYN020102000 | D32: 1 | E32: =Компонети!$F$20 -> 180 | F32: =E32*D32 -> 180
C33: VBS127010010 | D33: 1 | E33: =Компонети!$F$21 -> 44.4 | F33: =E33*D33 -> 44.4
C34: CIP138100020 | D34: 2 | E34: =Компонети!$F$22 -> 9.12 | F34: =E34*D34 -> 18.24
C35: CIP138200020 | D35: 1 | E35: =Компонети!$F$24 -> 9.12 | F35: =E35*D35 -> 9.12
C36: SUNPOW51100 | D36: 2 | E36: =Компонети!$F$32 -> 1226 | F36: =E36*D36 -> 2452
C37: 62 | D37: 1 | E37: =Компонети!$F$34 -> 75 | F37: =E37*D37 -> 75
C38: INS48305080 | D38: 1 | E38: =Компонети!$F$38 -> 50 | F38: =E38*D38 -> 50
C39: ESR1916U | D39: 1 | E39: =Компонети!$F$42 -> 100 | F39: =E39*D39 -> 100
C40: ESS1901U | D40: 2 | E40: =Компонети!$F$45 -> 20 | F40: =E40*D40 -> 40
...

Sheet Quattro & Sunlight
A1: Комплекти 230В, однофазні
A2: Total Energo | B2: Комплект безперебійного живлення 230В 5кВА – 4кВт з акумулятором 10кВт*г з WiFi | C2: TQS4802001005GX | D2: Кількість | E2: Вартість з ПДВ | F2: Варість * Кількість | H2: Артикул | I2: Ціна
C3: BPP900451100 | D3: 1 | E3: =Компонети!$F$19 -> 318 | F3: =E3*D3 -> 318 | H3: =C2 -> TQS4802001005GX | I3: =F14 -> 4740.96
C4: QUA482504010 | D4: 1 | E4: =Компонети!$F$11 -> 1429.2 | F4: =E4*D4 -> 1429.2 | H4: =C15 -> TQS4803001005GX | I4: =F27 -> 5996.08
C5: LYN020102000 | D5: 1 | E5: =Компонети!$F$20 -> 180 | F5: =E5*D5 -> 180 | H5: =C28 -> TQS4802001008GX | I5: =F40 -> 5731.96
C6: VBS127010010 | D6: 1 | E6: =Компонети!$F$21 -> 44.4 | F6: =E6*D6 -> 44.4 | H6: =C41 -> TQS4803001008GX | I6: =F53 -> 6987.08
C7: CIP138100020 | D7: 2 | E7: =Компонети!$F$22 -> 9.12 | F7: =E7*D7 -> 18.24 | H7: =C54 -> TQS4803001010GX | I7: =F66 -> 7498.28
C8: CIP138200020 | D8: 1 | E8: =Компонети!$F$24 -> 9.12 | F8: =E8*D8 -> 9.12 | H8: =C67 -> TQS4804001010GX | I8: =F79 -> 8953.4
C9: SUNPOW51100 | D9: 2 | E9: =Компонети!$F$32 -> 1226 | F9: =E9*D9 -> 2452 | H9: =C80 -> TQS4805001010GX | I9: =F92 -> 10213.52
C10: 63 | D10: 1 | E10: =Компонети!$F$35 -> 100 | F10: =E10*D10 -> 100 | H10: =C93 -> TQS4804001015GX | I10: =F105 -> 9860.12
C11: INS48305080 | D11: 1 | E11: =Компонети!$F$38 -> 50 | F11: =E11*D11 -> 50 | H11: =C106 -> TQS4805001015GX | I11: =F118 -> 11120.24
C12: ESR1916U | D12: 1 | E12: =Компонети!$F$42 -> 100 | F12: =E12*D12 -> 100 | H12: =C119 -> TQS4806001015GX | I12: =F131 -> 12375.36
C13: ESS1901U | D13: 2 | E13: =Компонети!$F$45 -> 20 | F13: =E13*D13 -> 40 | H13: =C134 -> TQS4803003015GX | I13: =F146 -> 9341.52
E14: Сума підсумкова | F14: =SUM(F3:F13) -> 4740.96 | H14: =C147 -> TQS4804003015GX | I14: =F159 -> 10616.64
A15: Total Energo | B15: Комплект безперебійного живлення 230В 5кВА – 4кВт з акумулятором 15кВт*г з WiFi | C15: TQS4803001005GX | F15: =E15*D15 -> 0 | H15: =C160 -> TQS4805003015GX | I15: =F172 -> 11876.76
C16: BPP900451100 | D16: 1 | E16: =Компонети!$F$19 -> 318 | F16: =E16*D16 -> 318 | H16: =C173 -> TQS4805003024GX | I16: =F185 -> 14874.76
C17: QUA482504010 | D17: 1 | E17: =Компонети!$F$11 -> 1429.2 | F17: =E17*D17 -> 1429.2 | H17: =C186 -> TQS4806003024GX | I17: =F198 -> 16309.88
C18: LYN020102000 | D18: 1 | E18: =Компонети!$F$20 -> 180 | F18: =E18*D18 -> 180 | H18: =C199 -> TQS4808003024GX | I18: =F211 -> 18935.12
C19: VBS127010010 | D19: 1 | E19: =Компонети!$F$21 -> 44.4 | F19: =E19*D19 -> 44.4 | H19: =C212 -> TQS4808003030GX | I19: =F224 -> 20676.08
C20: CIP138100020 | D20: 3 | E20: =Компонети!$F$22 -> 9.12 | F20: =E20*D20 -> 27.36 | H20: =C225 -> TQS4810003030GX | I20: =F237 -> 23196.32
C21: CIP138200020 | D21: 1 | E21: =Компонети!$F$24 -> 9.12 | F21: =E21*D21 -> 9.12 | H21: =C238 -> TQS4812003030GX | I21: =F250 -> 25886.56
C22: SUNPOW51100 | D22: 3 | E22: =Компонети!$F$32 -> 1226 | F22: =E22*D22 -> 3678 | H22: =C251 -> TQS4812003045GX | I22: =F263 -> 28579.36
C23: 63 | D23: 1 | E23: =Компонети!$F$35 -> 100 | F23: =E23*D23 -> 100 | H23: =C264 -> TQS4815003045GX | I23: =F276 -> 32649.72
C24: INS48305080 | D24: 1 | E24: =Компонети!$F$38 -> 50 | F24: =E24*D24 -> 50 | H24: =C277 -> TQS4818003045GX | I24: =F289 -> 36415.08
C25: ESR1916U | D25: 1 | E25: =Компонети!$F$42 -> 100 | F25: =E25*D25 -> 100 | H25: =C290 -> TQS4820003045GX | I25: =F302 -> 39105.32
C26: ESS1901U | D26: 3 | E26: =Компонети!$F$45 -> 20 | F26: =E26*D26 -> 60
E27: Сума підсумкова | F27: =SUM(F16:F26) -> 5996.08
A28: Total Energo | B28: Комплект безперебійного живлення 230В 8кВА – 6,4кВт з акумулятором 10кВт*г з WiFi | C28: TQS4802001008GX
C29: BPP900451100 | D29: 1 | E29: =Компонети!$F$19 -> 318 | F29: =E29*D29 -> 318
C30: QUA488024000 | D30: 1 | E30: =Компонети!$F$12 -> 2395.2 | F30: =E30*D30 -> 2395.2
C31: LYN020102000 | D31: 1 | E31: =Компонети!$F$20 -> 180 | F31: =E31*D31 -> 180
C32: VBS127010010 | D32: 1 | E32: =Компонети!$F$21 -> 44.4 | F32: =E32*D32 -> 44.4
C33: CIP138100020 | D33: 2 | E33: =Компонети!$F$22 -> 9.12 | F33: =E33*D33 -> 18.24
C34: CIP138300020 | D34: 1 | E34: =Компонети!$F$26 -> 9.12 | F34: =E34*D34 -> 9.12
C35: SUNPOW51100 | D35: 2 | E35: =Компонети!$F$32 -> 1226 | F35: =E35*D35 -> 2452
C36: 63 | D36: 1 | E36: =Компонети!$F$35 -> 100 | F36: =E36*D36 -> 100
C37: INS48100150 | D37: 1 | E37: =Компонети!$F$39 -> 75 | F37: =E37*D37 -> 75
C38: ESR1916U | D38: 1 | E38: =Компонети!$F$42 -> 100 | F38: =E38*D38 -> 100
C39: ESS1901U | D39: 2 | E39: =Компонети!$F$45 -> 20 | F39: =E39*D39 -> 40
E40: Сума підсумкова | F40: =SUM(F29:F39) -> 5731.96
...

Sheet Технічні параметри 230В
B1: Однофазні – MultiPlus | N1: Однофазні – Quattro
A2: Параметр | B2: ='MultiPlus & Sunlight'!C2 -> TMS4801001003 | C2: ='MultiPlus & Sunlight'!C10 -> TMS4801001003GX | D2: ='MultiPlus & Sunlight'!C18 -> TMS4802001005 | E2: ='MultiPlus & Sunlight'!C30 -> TMS4802001005GX | F2: ='MultiPlus & Sunlight'!C42 -> TMS4803001005GX | G2: ='MultiPlus & Sunlight'!C54 -> TMS4802001008GX | H2: ='MultiPlus & Sunlight'!C67 -> TMS4803001008GX | I2: ='MultiPlus & Sunlight'!C80 -> TMS4803001010GX | J2: ='MultiPlus & Sunlight'!C93 -> TMS4804001010GX | K2: ='MultiPlus & Sunlight'!C106 -> TMS4804001015GX | L2: ='MultiPlus & Sunlight'!C119 -> TMS4805001015GX | M2: ='MultiPlus & Sunlight'!C132 -> TMS4806001015GX | N2: ='Quattro & Sunlight'!C2 -> TQS4802001005GX | O2: ='Quattro & Sunlight'!C15 -> TQS4803001005GX | P2: ='Quattro & Sunlight'!C28 -> TQS4802001008GX | Q2: ='Quattro & Sunlight'!C41 -> TQS4803001008GX | R2: ='Quattro & Sunlight'!C54 -> TQS4803001010GX | S2: ='Quattro & Sunlight'!C67 -> TQS4804001010GX | T2: ='Quattro & Sunlight'!C80 -> TQS4805001010GX | U2: ='Quattro & Sunlight'!C93 -> TQS4804001015GX | V2: ='Quattro & Sunlight'!C106 -> TQS4805001015GX | W2: ='Quattro & Sunlight'!C119 -> TQS4806001015GX
A3: Мережа | B3: однофазна | C3: однофазна | D3: однофазна | E3: однофазна | F3: однофазна | G3: однофазна | H3: однофазна | I3: однофазна | J3: однофазна | K3: однофазна | L3: однофазна | M3: однофазна | N3: однофазна | O3: однофазна | P3: однофазна | Q3: однофазна | R3: однофазна | S3: однофазна | T3: однофазна | U3: однофазна | V3: однофазна | W3: однофазна
A4: Вхідна напруга, В | B4: 230 | C4: 230 | D4: 230 | E4: 230 | F4: 230 | G4: 230 | H4: 230 | I4: 230 | J4: 230 | K4: 230 | L4: 230 | M4: 230 | N4: 230 | O4: 230 | P4: 230 | Q4: 230 | R4: 230 | S4: 230 | T4: 230 | U4: 230 | V4: 230 | W4: 230
A5: Вихідна напруга, В | B5: 230 | C5: 230 | D5: 230 | E5: 230 | F5: 230 | G5: 230 | H5: 230 | I5: 230 | J5: 230 | K5: 230 | L5: 230 | M5: 230 | N5: 230 | O5: 230 | P5: 230 | Q5: 230 | R5: 230 | S5: 230 | T5: 230 | U5: 230 | V5: 230 | W5: 230
A6: Потужність вихідна від мережі, кВт | B6: 7.36 | C6: 7.36 | D6: 11 | E6: 11 | F6: 11 | G6: 22 | H6: 22 | I6: 22 | J6: 22 | K6: 22 | L6: 22 | M6: 22 | N6: 22 | O6: 22 | P6: 22 | Q6: 22 | R6: 22 | S6: 22 | T6: 22 | U6: 22 | V6: 22 | W6: 22
A7: Потужність вихідна від АКБ, кВА | B7: 3 | C7: 3 | D7: 5 | E7: 5 | F7: 5 | G7: 8 | H7: 8 | I7: 10 | J7: 10 | K7: 15 | L7: 15 | M7: 15 | N7: 5 | O7: 5 | P7: 8 | Q7: 8 | R7: 10 | S7: 10 | T7: 10 | U7: 15 | V7: 15 | W7: 15
A8: Потужність вихідна від АКБ, кВт | B8: 2.4 | C8: 2.4 | D8: 4 | E8: 4 | F8: 4 | G8: 6.4 | H8: 6.4 | I8: 8 | J8: 8 | K8: 12 | L8: 12 | M8: 12 | N8: 4 | O8: 4 | P8: 6.4 | Q8: 6.4 | R8: 8 | S8: 8 | T8: 8 | U8: 12 | V8: 12 | W8: 12
A9: Потужнісь вихідна пікова від АКБ, кВт | B9: 5.5 | C9: 5.5 | D9: 9 | E9: 9 | F9: 9 | G9: 15 | H9: 15 | I9: 18 | J9: 18 | K9: 27 | L9: 27 | M9: 27 | N9: 10 | O9: 10 | P9: 16 | Q9: 16 | R9: 20 | S9: 20 | T9: 20 | U9: 25 | V9: 25 | W9: 25
A10: Ємність АКБ, Аг | B10: 100 | C10: 100 | D10: 200 | E10: 200 | F10: 300 | G10: 200 | H10: 300 | I10: 300 | J10: 400 | K10: 400 | L10: 500 | M10: 600 | N10: 200 | O10: 300 | P10: 200 | Q10: 300 | R10: 300 | S10: 400 | T10: 500 | U10: 400 | V10: 500 | W10: 600
A11: Напруга АКБ, В | B11: 51.2 | C11: 51.2 | D11: 51.2 | E11: 51.2 | F11: 51.2 | G11: 51.2 | H11: 51.2 | I11: 51.2 | J11: 51.2 | K11: 51.2 | L11: 51.2 | M11: 51.2 | N11: 51.2 | O11: 51.2 | P11: 51.2 | Q11: 51.2 | R11: 51.2 | S11: 51.2 | T11: 51.2 | U11: 51.2 | V11: 51.2 | W11: 51.2
A12: Запас енергії у АКБ 100%, кВт*г | B12: =B10*B11/1000 -> 5.12 | C12: =C10*C11/1000 -> 5.12 | D12: =D10*D11/1000 -> 10.24 | E12: =E10*E11/1000 -> 10.24 | F12: =F10*F11/1000 -> 15.36 | G12: =G10*G11/1000 -> 10.24 | H12: =H10*H11/1000 -> 15.36 | I12: =I10*I11/1000 -> 15.36 | ... W12: =W10*W11/1000 -> 30.72
A13: Струм зарядного пристрою, А | B13: 35 | C13: 35 | D13: 70 | E13: 70 | F13: 70 | G13: 110 | H13: 110 | I13: 140 | J13: 140 | K13: 200 | L13: 200 | M13: 200 | N13: 70 | O13: 70 | P13: 110 | Q13: 110 | R13: 140 | S13: 140 | T13: 140 | U13: 200 | V13: 200 | W13: 200
A14: Час перезаряду 20-100%, годин | B14: =B10*0.8/B13 -> 2.2857143 | C14: =C10*0.8/C13 -> 2.2857143 | D14: =D10*0.8/D13 -> 2.2857143 | E14: =E10*0.8/E13 -> 2.2857143 | F14: =F10*0.8/F13 -> 3.4285714 | G14: =G10*0.8/(G13-10) -> 1.6 | H14: =H10*0.8/H13 -> 2.1818182 | I14: =I10*0.8/I13 -> 1.7142857 | J14: =J10*0.8/J13 -> 2.2857143 | K14: =K10*0.8/K13 -> 1.6 | L14: =L10*0.8/L13 -> 2 | M14: =M10*0.8/M13 -> 2.4 | N14: =N10*0.8/N13 -> 2.2857143 | O14: =O10*0.8/O13 -> 3.4285714 | P14: =P10*0.8/(P13-10) -> 1.6 | Q14: =Q10*0.8/(Q13-10) -> 2.4 | R14: =R10*0.8/R13 -> 1.7142857 | S14: =S10*0.8/S13 -> 2.2857143 | T14: =T10*0.8/T13 -> 2.8571429 | U14: =U10*0.8/U13 -> 1.6 | V14: =V10*0.8/V13 -> 2 | W14: =W10*0.8/W13 -> 2.4
A15: Час автономії при 1кВт 230В, годин | B15: =B10*0.95*0.96*B11/1000 -> 4.66944 | C15: =C10*0.95*0.96*C11/1000 -> 4.66944 | D15: =D10*0.95*0.96*D11/1000 -> 9.33888 | E15: =E10*0.95*0.96*E11/1000 -> 9.33888 | F15: =F10*0.95*0.96*F11/1000 -> 14.00832 | G15: =G10*0.95*0.96*G11/1000 -> 9.33888 | H15: =H10*0.95*0.96*H11/1000 -> 14.00832 | I15: =I10*0.95*0.96*I11/1000 -> 14.00832 | ... W15: =W10*0.95*0.96*W11/1000 -> 28.01664
A16: Час автономії при 2кВт 230В, годин | B16: =B10*0.95*0.95*B11/2000 -> 2.3104 | C16: =C10*0.95*0.95*C11/2000 -> 2.3104 | D16: =D10*0.95*0.95*D11/2000 -> 4.6208 | E16: =E10*0.95*0.95*E11/2000 -> 4.6208 | F16: =F10*0.95*0.95*F11/2000 -> 6.9312 | G16: =G10*0.95*0.95*G11/2000 -> 4.6208 | H16: =H10*0.95*0.95*H11/2000 -> 6.9312 | I16: =I10*0.95*0.95*I11/2000 -> 6.9312 | ... W16: =W10*0.95*0.95*W11/2000 -> 13.8624
A17: Час автономії при 3кВт 230В, годин | D17: =D10*0.95*0.95*D11/3000 -> 3.0805333 | E17: =E10*0.95*0.95*E11/3000 -> 3.0805333 | F17: =F10*0.95*0.95*F11/3000 -> 4.6208 | G17: =G10*0.95*0.95*G11/3000 -> 3.0805333 | H17: =H10*0.95*0.95*H11/3000 -> 4.6208 | I17: =I10*0.95*0.95*I11/3000 -> 4.6208 | J17: =J10*0.95*0.95*J11/3000 -> 6.1610667 | K17: =K10*0.95*0.95*K11/3000 -> 6.1610667 | ... W17: =W10*0.95*0.95*W11/3000 -> 9.2416
A18: Час автономії при 4кВт 230В, годин | D18: =D10*0.95*0.95*D11/4000 -> 2.3104 | E18: =E10*0.95*0.95*E11/4000 -> 2.3104 | F18: =F10*0.95*0.95*F11/4000 -> 3.4656 | G18: =G10*0.95*0.95*G11/4000 -> 2.3104 | H18: =H10*0.95*0.95*H11/4000 -> 3.4656 | I18: =I10*0.95*0.95*I11/4000 -> 3.4656 | J18: =J10*0.95*0.95*J11/4000 -> 4.6208 | K18: =K10*0.95*0.95*K11/4000 -> 4.6208 | ... W18: =W10*0.95*0.95*W11/4000 -> 6.9312
A19: Час автономії при 5кВт 230В, годин | G19: =G10*0.95*0.95*G11/5000 -> 1.84832 | H19: =H10*0.95*0.95*H11/5000 -> 2.77248 | I19: =I10*0.95*0.95*I11/5000 -> 2.77248 | J19: =J10*0.95*0.95*J11/5000 -> 3.69664 | K19: =K10*0.95*0.95*K11/5000 -> 3.69664 | L19: =L10*0.95*0.95*L11/5000 -> 4.6208 | M19: =M10*0.95*0.95*M11/5000 -> 5.54496 | P19: =P10*0.95*0.95*P11/5000 -> 1.84832 | Q19: =Q10*0.95*0.95*Q11/5000 -> 2.77248 | R19: =R10*0.95*0.95*R11/5000 -> 2.77248 | S19: =S10*0.95*0.95*S11/5000 -> 3.69664 | T19: =T10*0.95*0.95*T11/5000 -> 4.6208 | U19: =U10*0.95*0.95*U11/5000 -> 3.69664 | V19: =V10*0.95*0.95*V11/5000 -> 4.6208 | W19: =W10*0.95*0.95*W11/5000 -> 5.54496
A20: Час автономії при 6кВт 230В, годин | G20: =G10*0.95*0.95*G11/6000 -> 1.5402667 | H20: =H10*0.95*0.95*H11/6000 -> 2.3104 | I20: =I10*0.95*0.95*I11/6000 -> 2.3104 | J20: =J10*0.95*0.95*J11/6000 -> 3.0805333 | K20: =K10*0.95*0.95*K11/6000 -> 3.0805333 | L20: =L10*0.95*0.95*L11/6000 -> 3.8506667 | M20: =M10*0.95*0.95*M11/6000 -> 4.6208 | P20: =P10*0.95*0.95*P11/6000 -> 1.5402667 | Q20: =Q10*0.95*0.95*Q11/6000 -> 2.3104 | R20: =R10*0.95*0.95*R11/6000 -> 2.3104 | S20: =S10*0.95*0.95*S11/6000 -> 3.0805333 | T20: =T10*0.95*0.95*T11/6000 -> 3.8506667 | U20: =U10*0.95*0.95*U11/6000 -> 3.0805333 | V20: =V10*0.95*0.95*V11/6000 -> 3.8506667 | W20: =W10*0.95*0.95*W11/6000 -> 4.6208
A21: Час автономії при 8кВт 230В, годин | I21: =I10*0.95*0.95*I11/8000 -> 1.7328 | J21: =J10*0.95*0.95*J11/8000 -> 2.3104 | K21: =K10*0.95*0.95*K11/8000 -> 2.3104 | L21: =L10*0.95*0.95*L11/8000 -> 2.888 | M21: =M10*0.95*0.95*M11/8000 -> 3.4656 | R21: =R10*0.95*0.95*R11/8000 -> 1.7328 | S21: =S10*0.95*0.95*S11/8000 -> 2.3104 | T21: =T10*0.95*0.95*T11/8000 -> 2.888 | U21: =U10*0.95*0.95*U11/8000 -> 2.3104 | V21: =V10*0.95*0.95*V11/8000 -> 2.888 | W21: =W10*0.95*0.95*W11/8000 -> 3.4656
A22: Час автономії при 10кВт 230В, годин | K22: =K10*0.95*0.95*K11/10000 -> 1.84832 | L22: =L10*0.95*0.95*L11/10000 -> 2.3104 | M22: =M10*0.95*0.95*M11/10000 -> 2.77248 | U22: =U10*0.95*0.95*U11/10000 -> 1.84832 | V22: =V10*0.95*0.95*V11/10000 -> 2.3104 | W22: =W10*0.95*0.95*W11/10000 -> 2.77248
A23: Ресурс АКБ, циклів | B23: 6000 | C23: 6000 | D23: 6000 | E23: 6000 | F23: 6000 | G23: 6000 | H23: 6000 | I23: 6000 | J23: 6000 | K23: 6000 | L23: 6000 | M23: 6000 | N23: 6000 | O23: 6000 | P23: 6000 | Q23: 6000 | R23: 6000 | S23: 6000 | T23: 6000 | U23: 6000 | V23: 6000 | W23: 6000
A24: Ресурс АКБ, років | B24: 15 | C24: 15 | D24: 15 | E24: 15 | F24: 15 | G24: 15 | H24: 15 | I24: 15 | J24: 15 | K24: 15 | L24: 15 | M24: 15 | N24: 15 | O24: 15 | P24: 15 | Q24: 15 | R24: 15 | S24: 15 | T24: 15 | U24: 15 | V24: 15 | W24: 15
A25: Можливість збільшення АКБ | B25: Так | C25: Так | D25: Так | E25: Так | F25: Так | G25: Так | H25: Так | I25: Так | J25: Так | K25: Так | L25: Так | M25: Так | N25: Так | O25: Так | P25: Так | Q25: Так | R25: Так | S25: Так | T25: Так | U25: Так | V25: Так | W25: Так
A26: Модернізація у сонячну станцію | B26: Так | C26: Так | D26: Так | E26: Так | F26: Так | G26: Так | H26: Так | I26: Так | J26: Так | K26: Так | L26: Так | M26: Так | N26: Так | O26: Так | P26: Так | Q26: Так | R26: Так | S26: Так | T26: Так | U26: Так | V26: Так | W26: Так
A27: Підтримує роботу від генератора | B27: через АВР | C27: через АВР | D27: через АВР | E27: через АВР | F27: через АВР | G27: через АВР | H27: через АВР | I27: через АВР | J27: через АВР | K27: через АВР | L27: через АВР | M27: через АВР | N27: Автоматично | O27: Автоматично | P27: Автоматично | Q27: Автоматично | R27: Автоматично | S27: Автоматично | T27: Автоматично | U27: Автоматично | V27: Автоматично | W27: Автоматично
A28: Підтримка СЦ через інтернет | B28: Опція | C28: Так | D28: Опція | E28: Так | F28: Так | G28: Так | H28: Так | I28: Так | J28: Так | K28: Так | L28: Так | M28: Так | N28: Так | O28: Так | P28: Так | Q28: Так | R28: Так | S28: Так | T28: Так | U28: Так | V28: Так | W28: Так
A29: Контроль через Bluetooth | B29: Опція | C29: Так | D29: Опція | E29: Так | F29: Так | G29: Так | H29: Так | I29: Так | J29: Так | K29: Так | L29: Так | M29: Так | N29: Так | O29: Так | P29: Так | Q29: Так | R29: Так | S29: Так | T29: Так | U29: Так | V29: Так | W29: Так
A30: Контроль через Ethernet / WEB | B30: Опція | C30: Так | D30: Опція | E30: Так | F30: Так | G30: Так | H30: Так | I30: Так | J30: Так | K30: Так | L30: Так | M30: Так | N30: Так | O30: Так | P30: Так | Q30: Так | R30: Так | S30: Так | T30: Так | U30: Так | V30: Так | W30: Так
A31: Контроль через WiFi / WEB | B31: Опція | C31: Так | D31: Опція | E31: Так | F31: Так | G31: Так | H31: Так | I31: Так | J31: Так | K31: Так | L31: Так | M31: Так | N31: Так | O31: Так | P31: Так | Q31: Так | R31: Так | S31: Так | T31: Так | U31: Так | V31: Так | W31: Так
A32: Форма вихідного сигналу | B32: Синосоїда | C32: Синосоїда | D32: Синосоїда | E32: Синосоїда | F32: Синосоїда | G32: Синосоїда | H32: Синосоїда | I32: Синосоїда | J32: Синосоїда | K32: Синосоїда | L32: Синосоїда | M32: Синосоїда | N32: Синосоїда | O32: Синосоїда | P32: Синосоїда | Q32: Синосоїда | R32: Синосоїда | S32: Синосоїда | T32: Синосоїда | U32: Синосоїда | V32: Синосоїда | W32: Синосоїда
A33: ККД системи, % | B33: 96 | C33: 96 | D33: 96 | E33: 96 | F33: 96 | G33: 95 | H33: 95 | I33: 96 | J33: 96 | K33: 95 | L33: 95 | M33: 95 | N33: 96 | O33: 96 | P33: 95 | Q33: 95 | R33: 96 | S33: 96 | T33: 96 | U33: 95 | V33: 95 | W33: 95
A34: Додавання потужності до мережі | B34: Так | C34: Так | D34: Так | E34: Так | F34: Так | G34: Так | H34: Так | I34: Так | J34: Так | K34: Так | L34: Так | M34: Так | N34: Так | O34: Так | P34: Так | Q34: Так | R34: Так | S34: Так | T34: Так | U34: Так | V34: Так | W34: Так
A35: Мінімальна температура розряду, °С | B35: –20 | C35: –20 | D35: –20 | E35: –20 | F35: –20 | G35: –20 | H35: –20 | I35: –20 | J35: –20 | K35: –20 | L35: –20 | M35: –20 | N35: –20 | O35: –20 | P35: –20 | Q35: –20 | R35: –20 | S35: –20 | T35: –20 | U35: –20 | V35: –20 | W35: –20
A36: Максимальна температура розряду, °С | B36: =55 -> 55 | C36: =55 -> 55 | D36: =55 -> 55 | E36: =55 -> 55 | F36: =55 -> 55 | G36: =55 -> 55 | H36: =55 -> 55 | I36: =55 -> 55 | ... W36: =55 -> 55
A37: Мінімальна температура заряду, °С | B37: =5 -> 5 | C37: =5 -> 5 | D37: =5 -> 5 | E37: =5 -> 5 | F37: =5 -> 5 | G37: =5 -> 5 | H37: =5 -> 5 | I37: =5 -> 5 | ... W37: =5 -> 5
A38: Максимальна температура заряду, °С | B38: 55 | C38: 55 | D38: 55 | E38: 55 | F38: 55 | G38: 55 | H38: 55 | I38: 55 | J38: 55 | K38: 55 | L38: 55 | M38: 55 | N38: 55 | O38: 55 | P38: 55 | Q38: 55 | R38: 55 | S38: 55 | T38: 55 | U38: 55 | V38: 55 | W38: 55
A39: Призначення | B39: аварійне живлення | C39: аварійне живлення | D39: аварійне живлення | E39: аварійне живлення | F39: аварійне живлення | G39: аварійне живлення | H39: аварійне живлення | I39: аварійне живлення | J39: аварійне живлення | K39: аварійне живлення | L39: аварійне живлення | M39: аварійне живлення | N39: аварійне живлення | O39: аварійне живлення | P39: аварійне живлення | Q39: аварійне живлення | R39: аварійне живлення | S39: аварійне живлення | T39: аварійне живлення | U39: аварійне живлення | V39: аварійне живлення | W39: аварійне живлення
B40: резервне живлення | C40: резервне живлення | D40: резервне живлення | E40: резервне живлення | F40: резервне живлення | G40: резервне живлення | H40: резервне живлення | I40: резервне живлення | J40: резервне живлення | K40: резервне живлення | L40: резервне живлення | M40: резервне живлення | N40: резервне живлення | O40: резервне живлення | P40: резервне живлення | Q40: резервне живлення | R40: резервне живлення | S40: резервне живлення | T40: резервне живлення | U40: резервне живлення | V40: резервне живлення | W40: резервне живлення
...

Sheet Технічні параметри 400В
B1: Трифазні – MultiPlus | R1: Трифазні – Quattro
A2: Параметр | B2: ='MultiPlus & Sunlight'!C146 -> TMS4802003009GX | C2: ='MultiPlus & Sunlight'!C159 -> TMS4803003009GX | D2: ='MultiPlus & Sunlight'!C172 -> TMS4804003009GX | E2: ='MultiPlus & Sunlight'!C185 -> TMS4803003015GX | F2: ='MultiPlus & Sunlight'!C198 -> TMS4804003015GX | G2: ='MultiPlus & Sunlight'!C211 -> TMS4805003015GX | H2: ='MultiPlus & Sunlight'!C224 -> TMS4805003024GX | I2: ='MultiPlus & Sunlight'!C237 -> TMS4806003024GX | J2: ='MultiPlus & Sunlight'!C250 -> TMS4808003024GX | K2: ='MultiPlus & Sunlight'!C263 -> TMS4810003024GX | L2: ='MultiPlus & Sunlight'!C276 -> TMS4808003030GX | M2: ='MultiPlus & Sunlight'!C289 -> TMS4810003030GX | N2: ='MultiPlus & Sunlight'!C315 -> TMS4809003045GX | O2: ='MultiPlus & Sunlight'!C328 -> TMS4812003045GX | P2: ='MultiPlus & Sunlight'!C341 -> TMS4815003045GX | R2: ='Quattro & Sunlight'!C134 -> TQS4803003015GX | S2: ='Quattro & Sunlight'!C147 -> TQS4804003015GX | T2: ='Quattro & Sunlight'!C160 -> TQS4805003015GX | U2: ='Quattro & Sunlight'!C173 -> TQS4805003024GX | V2: ='Quattro & Sunlight'!C186 -> TQS4806003024GX | W2: ='Quattro & Sunlight'!C199 -> TQS4808003024GX | X2: ='Quattro & Sunlight'!C212 -> TQS4808003030GX | Y2: ='Quattro & Sunlight'!C225 -> TQS4810003030GX | Z2: ='Quattro & Sunlight'!C238 -> TQS4812003030GX | AA2: ='Quattro & Sunlight'!C251 -> TQS4812003045GX | AB2: ='Quattro & Sunlight'!C264 -> TQS4815003045GX | AC2: ='Quattro & Sunlight'!C277 -> TQS4818003045GX | AD2: ='Quattro & Sunlight'!C290 -> TQS4820003045GX
A3: Мережа | B3: трифазна | C3: трифазна | D3: трифазна | E3: трифазна | F3: трифазна | G3: трифазна | H3: трифазна | I3: трифазна | J3: трифазна | K3: трифазна | L3: трифазна | M3: трифазна | N3: трифазна | O3: трифазна | P3: трифазна | R3: трифазна | S3: трифазна | T3: трифазна | U3: трифазна | V3: трифазна | W3: трифазна | X3: трифазна | Y3: трифазна | Z3: трифазна | AA3: трифазна | AB3: трифазна | AC3: трифазна | AD3: трифазна
A4: Вхідна напруга, В | B4: 400 | C4: 400 | D4: 400 | E4: 400 | F4: 400 | G4: 400 | H4: 400 | I4: 400 | J4: 400 | K4: 400 | L4: 400 | M4: 400 | N4: 400 | O4: 400 | P4: 400 | R4: 400 | S4: 400 | T4: 400 | U4: 400 | V4: 400 | W4: 400 | X4: 400 | Y4: 400 | Z4: 400 | AA4: 400 | AB4: 400 | AC4: 400 | AD4: 400
A5: Вихідна напруга, В | B5: 400 | C5: 400 | D5: 400 | E5: 400 | F5: 400 | G5: 400 | H5: 400 | I5: 400 | J5: 400 | K5: 400 | L5: 400 | M5: 400 | N5: 400 | O5: 400 | P5: 400 | R5: 400 | S5: 400 | T5: 400 | U5: 400 | V5: 400 | W5: 400 | X5: 400 | Y5: 400 | Z5: 400 | AA5: 400 | AB5: 400 | AC5: 400 | AD5: 400
A6: Потужність вихідна від мережі, кВт | B6: 22 | C6: 22 | D6: 22 | E6: 33 | F6: 33 | G6: 33 | H6: 66 | I6: 66 | J6: 66 | K6: 66 | L6: 66 | M6: 66 | N6: 66 | O6: 66 | P6: 66 | R6: 66 | S6: 66 | T6: 66 | U6: 66 | V6: 66 | W6: 66 | X6: 66 | Y6: 66 | Z6: 66 | AA6: 66 | AB6: 66 | AC6: 66 | AD6: 66
A7: Потужність вихідна від АКБ, кВА | B7: 9 | C7: 9 | D7: 9 | E7: 15 | F7: 15 | G7: 15 | H7: 24 | I7: 24 | J7: 24 | K7: 24 | L7: 30 | M7: 30 | N7: 45 | O7: 45 | P7: 45 | R7: 15 | S7: 15 | T7: 15 | U7: 24 | V7: 24 | W7: 24 | X7: 30 | Y7: 30 | Z7: 30 | AA7: 45 | AB7: 45 | AC7: 45 | AD7: 45
A8: Потужність вихідна від АКБ, кВт | B8: 7.2 | C8: 7.2 | D8: 7.2 | E8: 12 | F8: 12 | G8: 12 | H8: =6.4*3 -> 19.2 | I8: =6.4*3 -> 19.2 | J8: =6.4*3 -> 19.2 | K8: =6.4*3 -> 19.2 | L8: 24 | M8: 24 | N8: 36 | O8: 36 | P8: 36 | R8: 12 | S8: 12 | T8: 12 | U8: 19.2 | V8: 19.2 | W8: 19.2 | X8: 24 | Y8: 24 | Z8: 24 | AA8: 36 | AB8: 36 | AC8: 36 | AD8: 36
A9: Потужнісь вихідна пікова від АКБ, кВт | B9: =5.5*3 -> 16.5 | C9: =5.5*3 -> 16.5 | D9: =5.5*3 -> 16.5 | E9: 27 | F9: 27 | G9: 27 | H9: 45 | I9: 45 | J9: 45 | K9: 45 | L9: =18*3 -> 54 | M9: =18*3 -> 54 | N9: 75 | O9: 75 | P9: 75 | R9: 30 | S9: 30 | T9: 30 | U9: =16*3 -> 48 | V9: =16*3 -> 48 | W9: =16*3 -> 48 | X9: 60 | Y9: 60 | Z9: 60 | AA9: 75 | AB9: 75 | AC9: 75 | AD9: 75
A10: Ємність АКБ, Аг | B10: 200 | C10: 300 | D10: 400 | E10: 300 | F10: 400 | G10: 500 | H10: 500 | I10: 600 | J10: 800 | K10: 1000 | L10: 800 | M10: 1000 | N10: 900 | O10: 1200 | P10: 1500 | R10: 300 | S10: 400 | T10: 500 | U10: 500 | V10: 600 | W10: 800 | X10: 800 | Y10: 1000 | Z10: 1200 | AA10: 1200 | AB10: 1500 | AC10: 1800 | AD10: 2000
A11: Напруга АКБ, В | B11: 51.2 | C11: 51.2 | D11: 51.2 | E11: 51.2 | F11: 51.2 | G11: 51.2 | H11: 51.2 | I11: 51.2 | J11: 51.2 | K11: 51.2 | L11: 51.2 | M11: 51.2 | N11: 51.2 | O11: 51.2 | P11: 51.2 | R11: 51.2 | S11: 51.2 | T11: 51.2 | U11: 51.2 | V11: 51.2 | W11: 51.2 | X11: 51.2 | Y11: 51.2 | Z11: 51.2 | AA11: 51.2 | AB11: 51.2 | AC11: 51.2 | AD11: 51.2
A12: Запас енергії у АКБ 100%, кВт*г | B12: =B10*B11/1000 -> 10.24 | C12: =C10*C11/1000 -> 15.36 | D12: =D10*D11/1000 -> 20.48 | E12: =E10*E11/1000 -> 15.36 | F12: =F10*F11/1000 -> 20.48 | G12: =G10*G11/1000 -> 25.6 | H12: =H10*H11/1000 -> 25.6 | I12: =I10*I11/1000 -> 30.72 | ... P12: =P10*P11/1000 -> 76.8 | R12: =R10*R11/1000 -> 15.36 | S12: =S10*S11/1000 -> 20.48 | T12: =T10*T11/1000 -> 25.6 | U12: =U10*U11/1000 -> 25.6 | V12: =V10*V11/1000 -> 30.72 | W12: =W10*W11/1000 -> 40.96 | X12: =X10*X11/1000 -> 40.96 | Y12: =Y10*Y11/1000 -> 51.2 | ... AD12: =AD10*AD11/1000 -> 102.4
A13: Струм зарядного пристрою, А | B13: 105 | C13: 105 | D13: 105 | E13: 210 | F13: 210 | G13: 210 | H13: =110*3 -> 330 | I13: =110*3 -> 330 | J13: =110*3 -> 330 | K13: =110*3 -> 330 | L13: =140*3 -> 420 | M13: =140*3 -> 420 | N13: 600 | O13: 600 | P13: 600 | R13: 210 | S13: 210 | T13: 210 | U13: =110*3 -> 330 | V13: =110*3 -> 330 | W13: =110*3 -> 330 | X13: =140*3 -> 420 | Y13: =140*3 -> 420 | Z13: =140*3 -> 420 | AA13: =200*3 -> 600 | AB13: =200*3 -> 600 | AC13: =200*3 -> 600 | AD13: =200*3 -> 600
A14: Час перезаряду 20-100%, годин | B14: =B10*0.8/(B13-5) -> 1.6 | C14: =C10*0.8/(C13-5) -> 2.4 | D14: =D10*0.8/(D13-5) -> 3.2 | E14: =E10*0.8/(150) -> 1.6 | F14: =F10*0.8/(200) -> 1.6 | G14: =G10*0.8/(G13) -> 1.9047619 | H14: =H10*0.8/(250) -> 1.6 | I14: =I10*0.8/(300) -> 1.6 | J14: =J10*0.8/J13 -> 1.9393939 | K14: =K10*0.8/K13 -> 2.4242424 | L14: =L10*0.8/L13 -> 1.5238095 | M14: =M10*0.8/M13 -> 1.9047619 | N14: =N10*0.8/450 -> 1.6 | O14: =O10*0.8/O13 -> 1.6 | P14: =P10*0.8/P13 -> 2 | R14: =R10*0.8/(150) -> 1.6 | S14: =S10*0.8/(200) -> 1.6 | T14: =T10*0.8/T13 -> 1.9047619 | U14: =U10*0.8/(250) -> 1.6 | V14: =V10*0.8/(300) -> 1.6 | W14: =W10*0.8/330 -> 1.9393939 | X14: =X10*0.8/X13 -> 1.5238095 | Y14: =Y10*0.8/Y13 -> 1.9047619 | Z14: =Z10*0.8/Z13 -> 2.2857143 | AA14: =AA10*0.8/AA13 -> 1.6 | AB14: =AB10*0.8/AB13 -> 2 | AC14: =AC10*0.8/AC13 -> 2.4 | AD14: =AD10*0.8/AD13 -> 2.6666667
A15: Час автономії при 3кВт 400В, годин | B15: =B10*0.95*0.96*B11/3000 -> 3.11296 | C15: =C10*0.95*0.96*C11/3000 -> 4.66944 | D15: =D10*0.95*0.96*D11/3000 -> 6.22592 | E15: =E10*0.95*0.96*E11/3000 -> 4.66944 | F15: =F10*0.95*0.96*F11/3000 -> 6.22592 | G15: =G10*0.95*0.96*G11/3000 -> 7.7824 | H15: =H10*0.95*0.96*H11/3000 -> 7.7824 | I15: =I10*0.95*0.96*I11/3000 -> 9.33888 | ... P15: =P10*0.95*0.96*P11/3000 -> 23.3472 | R15: =R10*0.95*0.96*R11/3000 -> 4.66944 | S15: =S10*0.95*0.96*S11/3000 -> 6.22592 | T15: =T10*0.95*0.96*T11/3000 -> 7.7824 | U15: =U10*0.95*0.96*U11/3000 -> 7.7824 | V15: =V10*0.95*0.96*V11/3000 -> 9.33888 | W15: =W10*0.95*0.96*W11/3000 -> 12.45184 | X15: =X10*0.95*0.96*X11/3000 -> 12.45184 | Y15: =Y10*0.95*0.96*Y11/3000 -> 15.5648 | ... AD15: =AD10*0.95*0.96*AD11/3000 -> 31.1296
A16: Час автономії при 5кВт 400В, годин | B16: =B10*0.95*0.95*B11/5000 -> 1.84832 | C16: =C10*0.95*0.95*C11/5000 -> 2.77248 | D16: =D10*0.95*0.95*D11/5000 -> 3.69664 | E16: =E10*0.95*0.95*E11/5000 -> 2.77248 | F16: =F10*0.95*0.95*F11/5000 -> 3.69664 | G16: =G10*0.95*0.95*G11/5000 -> 4.6208 | H16: =H10*0.95*0.95*H11/5000 -> 4.6208 | I16: =I10*0.95*0.95*I11/5000 -> 5.54496 | ... P16: =P10*0.95*0.95*P11/5000 -> 13.8624 | R16: =R10*0.95*0.95*R11/5000 -> 2.77248 | S16: =S10*0.95*0.95*S11/5000 -> 3.69664 | T16: =T10*0.95*0.95*T11/5000 -> 4.6208 | U16: =U10*0.95*0.95*U11/5000 -> 4.6208 | V16: =V10*0.95*0.95*V11/5000 -> 5.54496 | W16: =W10*0.95*0.95*W11/5000 -> 7.39328 | X16: =X10*0.95*0.95*X11/5000 -> 7.39328 | Y16: =Y10*0.95*0.95*Y11/5000 -> 9.2416 | ... AD16: =AD10*0.95*0.95*AD11/5000 -> 18.4832
A17: Час автономії при 7кВт 400В, годин | B17: =B10*0.95*0.95*B11/7000 -> 1.3202286 | C17: =C10*0.95*0.95*C11/7000 -> 1.9803429 | D17: =D10*0.95*0.95*D11/7000 -> 2.6404571 | E17: =E10*0.95*0.95*E11/7000 -> 1.9803429 | F17: =F10*0.95*0.95*F11/7000 -> 2.6404571 | G17: =G10*0.95*0.95*G11/7000 -> 3.3005714 | H17: =H10*0.95*0.95*H11/7000 -> 3.3005714 | I17: =I10*0.95*0.95*I11/7000 -> 3.9606857 | ... P17: =P10*0.95*0.95*P11/7000 -> 9.9017143 | R17: =R10*0.95*0.95*R11/7000 -> 1.9803429 | S17: =S10*0.95*0.95*S11/7000 -> 2.6404571 | T17: =T10*0.95*0.95*T11/7000 -> 3.3005714 | U17: =U10*0.95*0.95*U11/7000 -> 3.3005714 | V17: =V10*0.95*0.95*V11/7000 -> 3.9606857 | W17: =W10*0.95*0.95*W11/7000 -> 5.2809143 | X17: =X10*0.95*0.95*X11/7000 -> 5.2809143 | Y17: =Y10*0.95*0.95*Y11/7000 -> 6.6011429 | ... AD17: =AD10*0.95*0.95*AD11/7000 -> 13.202286
A18: Час автономії при 10кВт 400В, годин | E18: =E10*0.95*0.95*E11/10000 -> 1.38624 | F18: =F10*0.95*0.95*F11/10000 -> 1.84832 | G18: =G10*0.95*0.95*G11/10000 -> 2.3104 | H18: =H10*0.95*0.95*H11/10000 -> 2.3104 | I18: =I10*0.95*0.95*I11/10000 -> 2.77248 | J18: =J10*0.95*0.95*J11/10000 -> 3.69664 | K18: =K10*0.95*0.95*K11/10000 -> 4.6208 | L18: =L10*0.95*0.95*L11/10000 -> 3.69664 | ... P18: =P10*0.95*0.95*P11/10000 -> 6.9312 | R18: =R10*0.95*0.95*R11/10000 -> 1.38624 | S18: =S10*0.95*0.95*S11/10000 -> 1.84832 | T18: =T10*0.95*0.95*T11/10000 -> 2.3104 | U18: =U10*0.95*0.95*U11/10000 -> 2.3104 | V18: =V10*0.95*0.95*V11/10000 -> 2.77248 | W18: =W10*0.95*0.95*W11/10000 -> 3.69664 | X18: =X10*0.95*0.95*X11/10000 -> 3.69664 | Y18: =Y10*0.95*0.95*Y11/10000 -> 4.6208 | ... AD18: =AD10*0.95*0.95*AD11/10000 -> 9.2416
A19: Час автономії при 12кВт 400В, годин | E19: =E10*0.95*0.95*E11/12000 -> 1.1552 | F19: =F10*0.95*0.95*F11/12000 -> 1.5402667 | G19: =G10*0.95*0.95*G11/12000 -> 1.9253333 | H19: =H10*0.95*0.95*H11/12000 -> 1.9253333 | I19: =I10*0.95*0.95*I11/12000 -> 2.3104 | J19: =J10*0.95*0.95*J11/12000 -> 3.0805333 | K19: =K10*0.95*0.95*K11/12000 -> 3.8506667 | L19: =L10*0.95*0.95*L11/12000 -> 3.0805333 | ... P19: =P10*0.95*0.95*P11/12000 -> 5.776 | R19: =R10*0.95*0.95*R11/12000 -> 1.1552 | S19: =S10*0.95*0.95*S11/12000 -> 1.5402667 | T19: =T10*0.95*0.95*T11/12000 -> 1.9253333 | U19: =U10*0.95*0.95*U11/12000 -> 1.9253333 | V19: =V10*0.95*0.95*V11/12000 -> 2.3104 | W19: =W10*0.95*0.95*W11/12000 -> 3.0805333 | X19: =X10*0.95*0.95*X11/12000 -> 3.0805333 | Y19: =Y10*0.95*0.95*Y11/12000 -> 3.8506667 | ... AD19: =AD10*0.95*0.95*AD11/12000 -> 7.7013333
A20: Час автономії при 15кВт 400В, годин | H20: =H10*0.95*0.95*H11/15000 -> 1.5402667 | I20: =I10*0.95*0.95*I11/15000 -> 1.84832 | J20: =J10*0.95*0.95*J11/15000 -> 2.4644267 | K20: =K10*0.95*0.95*K11/15000 -> 3.0805333 | L20: =L10*0.95*0.95*L11/15000 -> 2.4644267 | M20: =M10*0.95*0.95*M11/15000 -> 3.0805333 | N20: =N10*0.95*0.95*N11/15000 -> 2.77248 | O20: =O10*0.95*0.95*O11/15000 -> 3.69664 | P20: =P10*0.95*0.95*P11/15000 -> 4.6208 | U20: =U10*0.95*0.95*U11/15000 -> 1.5402667 | V20: =V10*0.95*0.95*V11/15000 -> 1.84832 | W20: =W10*0.95*0.95*W11/15000 -> 2.4644267 | X20: =X10*0.95*0.95*X11/15000 -> 2.4644267 | Y20: =Y10*0.95*0.95*Y11/15000 -> 3.0805333 | Z20: =Z10*0.95*0.95*Z11/15000 -> 3.69664 | AA20: =AA10*0.95*0.95*AA11/15000 -> 3.69664 | AB20: =AB10*0.95*0.95*AB11/15000 -> 4.6208 | ... AD20: =AD10*0.95*0.95*AD11/15000 -> 6.1610667
A21: Час автономії при 20кВт 400В, годин | L21: =L10*0.95*0.95*L11/20000 -> 1.84832 | M21: =M10*0.95*0.95*M11/20000 -> 2.3104 | N21: =N10*0.95*0.95*N11/20000 -> 2.07936 | O21: =O10*0.95*0.95*O11/20000 -> 2.77248 | P21: =P10*0.95*0.95*P11/20000 -> 3.4656 | X21: =X10*0.95*0.95*X11/20000 -> 1.84832 | Y21: =Y10*0.95*0.95*Y11/20000 -> 2.3104 | Z21: =Z10*0.95*0.95*Z11/20000 -> 2.77248 | AA21: =AA10*0.95*0.95*AA11/20000 -> 2.77248 | AB21: =AB10*0.95*0.95*AB11/20000 -> 3.4656 | AC21: =AC10*0.95*0.95*AC11/20000 -> 4.15872 | AD21: =AD10*0.95*0.95*AD11/20000 -> 4.6208
A22: Час автономії при 30кВт 400В, годин | N22: =N10*0.95*0.95*N11/30000 -> 1.38624 | O22: =O10*0.95*0.95*O11/30000 -> 1.84832 | P22: =P10*0.95*0.95*P11/30000 -> 2.3104 | AA22: =AA10*0.95*0.95*AA11/30000 -> 1.84832 | AB22: =AB10*0.95*0.95*AB11/30000 -> 2.3104 | AC22: =AC10*0.95*0.95*AC11/30000 -> 2.77248 | AD22: =AD10*0.95*0.95*AD11/30000 -> 3.0805333
A23: Ресурс АКБ, циклів | B23: 6000 | C23: 6000 | D23: 6000 | E23: 6000 | F23: 6000 | G23: 6000 | H23: 6000 | I23: 6000 | J23: 6000 | K23: 6000 | L23: 6000 | M23: 6000 | N23: 6000 | O23: 6000 | P23: 6000 | R23: 6000 | S23: 6000 | T23: 6000 | U23: 6000 | V23: 6000 | W23: 6000 | X23: 6000 | Y23: 6000 | Z23: 6000 | AA23: 6000 | AB23: 6000 | AC23: 6000 | AD23: 6000
A24: Ресурс АКБ, років | B24: 15 | C24: 15 | D24: 15 | E24: 15 | F24: 15 | G24: 15 | H24: 15 | I24: 15 | J24: 15 | K24: 15 | L24: 15 | M24: 15 | N24: 15 | O24: 15 | P24: 15 | R24: 15 | S24: 15 | T24: 15 | U24: 15 | V24: 15 | W24: 15 | X24: 15 | Y24: 15 | Z24: 15 | AA24: 15 | AB24: 15 | AC24: 15 | AD24: 15
A25: Можливість збільшення АКБ | B25: Так | C25: Так | D25: Так | E25: Так | F25: Так | G25: Так | H25: Так | I25: Так | J25: Так | K25: Так | L25: Так | M25: Так | N25: Так | O25: Так | P25: Так | R25: Так | S25: Так | T25: Так | U25: Так | V25: Так | W25: Так | X25: Так | Y25: Так | Z25: Так | AA25: Так | AB25: Так | AC25: Так | AD25: Так
A26: Модернізація у сонячну станцію | B26: Так | C26: Так | D26: Так | E26: Так | F26: Так | G26: Так | H26: Так | I26: Так | J26: Так | K26: Так | L26: Так | M26: Так | N26: Так | O26: Так | P26: Так | R26: Так | S26: Так | T26: Так | U26: Так | V26: Так | W26: Так | X26: Так | Y26: Так | Z26: Так | AA26: Так | AB26: Так | AC26: Так | AD26: Так
A27: Підтримує роботу від генератора | B27: через АВР | C27: через АВР | D27: через АВР | E27: через АВР | F27: через АВР | G27: через АВР | H27: через АВР | I27: через АВР | J27: через АВР | K27: через АВР | L27: через АВР | M27: через АВР | N27: через АВР | O27: через АВР | P27: через АВР | R27: Автоматично | S27: Автоматично | T27: Автоматично | U27: Автоматично | V27: Автоматично | W27: Автоматично | X27: Автоматично | Y27: Автоматично | Z27: Автоматично | AA27: Автоматично | AB27: Автоматично | AC27: Автоматично | AD27: Автоматично
A28: Підтримка СЦ через інтернет | B28: Так | C28: Так | D28: Так | E28: Так | F28: Так | G28: Так | H28: Так | I28: Так | J28: Так | K28: Так | L28: Так | M28: Так | N28: Так | O28: Так | P28: Так | R28: Так | S28: Так | T28: Так | U28: Так | V28: Так | W28: Так | X28: Так | Y28: Так | Z28: Так | AA28: Так | AB28: Так | AC28: Так | AD28: Так
A29: Контроль через Bluetooth | B29: Так | C29: Так | D29: Так | E29: Так | F29: Так | G29: Так | H29: Так | I29: Так | J29: Так | K29: Так | L29: Так | M29: Так | N29: Так | O29: Так | P29: Так | R29: Так | S29: Так | T29: Так | U29: Так | V29: Так | W29: Так | X29: Так | Y29: Так | Z29: Так | AA29: Так | AB29: Так | AC29: Так | AD29: Так
A30: Контроль через Ethernet / WEB | B30: Так | C30: Так | D30: Так | E30: Так | F30: Так | G30: Так | H30: Так | I30: Так | J30: Так | K30: Так | L30: Так | M30: Так | N30: Так | O30: Так | P30: Так | R30: Так | S30: Так | T30: Так | U30: Так | V30: Так | W30: Так | X30: Так | Y30: Так | Z30: Так | AA30: Так | AB30: Так | AC30: Так | AD30: Так
A31: Контроль через WiFi / WEB | B31: Так | C31: Так | D31: Так | E31: Так | F31: Так | G31: Так | H31: Так | I31: Так | J31: Так | K31: Так | L31: Так | M31: Так | N31: Так | O31: Так | P31: Так | R31: Так | S31: Так | T31: Так | U31: Так | V31: Так | W31: Так | X31: Так | Y31: Так | Z31: Так | AA31: Так | AB31: Так | AC31: Так | AD31: Так
A32: Форма вихідного сигналу | B32: Синосоїда | C32: Синосоїда | D32: Синосоїда | E32: Синосоїда | F32: Синосоїда | G32: Синосоїда | H32: Синосоїда | I32: Синосоїда | J32: Синосоїда | K32: Синосоїда | L32: Синосоїда | M32: Синосоїда | N32: Синосоїда | O32: Синосоїда | P32: Синосоїда | R32: Синосоїда | S32: Синосоїда | T32: Синосоїда | U32: Синосоїда | V32: Синосоїда | W32: Синосоїда | X32: Синосоїда | Y32: Синосоїда | Z32: Синосоїда | AA32: Синосоїда | AB32: Синосоїда | AC32: Синосоїда | AD32: Синосоїда
A33: ККД системи, % | B33: 96 | C33: 96 | D33: 96 | E33: 96 | F33: 96 | G33: 96 | H33: 96 | I33: 96 | J33: 96 | K33: 96 | L33: 96 | M33: 96 | N33: 96 | O33: 96 | P33: 96 | R33: 96 | S33: 96 | T33: 96 | U33: 96 | V33: 96 | W33: 96 | X33: 96 | Y33: 96 | Z33: 96 | AA33: 96 | AB33: 96 | AC33: 96 | AD33: 96
A34: Додавання потужності до мережі | B34: Так | C34: Так | D34: Так | E34: Так | F34: Так | G34: Так | H34: Так | I34: Так | J34: Так | K34: Так | L34: Так | M34: Так | N34: Так | O34: Так | P34: Так | R34: Так | S34: Так | T34: Так | U34: Так | V34: Так | W34: Так | X34: Так | Y34: Так | Z34: Так | AA34: Так | AB34: Так | AC34: Так | AD34: Так
